Workbook

Sheet Nivel 1
B9: Centro de trabajo: | C9: Oficina Central | D9: Cliente: | E9: Bimbo | F9: Total de Cumplimiento Informado:
B10: Administrador de obra: | C10: Franklin Bratta | D10: Fecha inicio del Proyecto: | E10: 45763
B11: Experto en Prevención de Riesgos de Obra: | C11: Loreto lopez | D11: Hora de Inicio: | E11: 0.5 | F11: Total de Cumplimiento Verificado: | H11: Cumple
B12: Fecha: | C12: 45763 | D12: Hora de Termino: | E12: 0.75 | F12: =G24 -> 0.57142857 | H12: No Cumple
H13: No Aplica
B14: LIDERAZGO Y COMPROMISO | D14: Cumple/No Cumple No Aplica | E14: OBSERVACIONES | G14: Subtotal
B15: 1.1. ¿Esta constituido el Comité Ejecutivo de Obra (CEO)? Mantiene acta de constitución y mensuales. | D15: Cumple | G15: =IF(D15="Cumple",1,IF(D15="No Cumple",0,"NA")) -> 1
B16: 1.2 ¿Se realiza una entrevista por el CEO a los trabajadores accidentados o que han declarado una enfermedad profesional? RG-SST-17 | D16: No Cumple | G16: =IF(D16="Cumple",1,IF(D16="No Cumple",0,"NA")) -> 0
B17: 1.3 ¿Se realiza de manera semanal una reunión de coordinación de obra para tratar temas de Prevención de Riesgos y Salud en el Trabajo? | D17: No Cumple | G17: =IF(D17="Cumple",1,IF(D17="No Cumple",0,"NA")) -> 0
B18: 1.4. ¿En la Reunión semanal de coordinación SST se aborda la planificación de actividades de la semana siguiente en la obra? (Carta Gantt) | D18: Cumple | G18: =IF(D18="Cumple",1,IF(D18="No Cumple",0,"NA")) -> 1
B19: 1.5. ¿Se registra en un acta los acuerdos establecidos, responsables de implementación de acciones y plazos de cumplimiento de cada una de las reuniones de SST? | D19: No Cumple | G19: =IF(D19="Cumple",1,IF(D19="No Cumple",0,"NA")) -> 0
B20: 1.6. ¿Todos tienen Programas de Liderazgo Participativo de SST, desde el Administrador hasta los capataces? RG-SST-110 | D20: Cumple | G20: =IF(D20="Cumple",1,IF(D20="No Cumple",0,"NA")) -> 1
B21: 1.7. ¿El Administrador de Obra o el Gerente Visitador difundieron la Política de SST? | D21: No Aplica | G21: =IF(D21="Cumple",1,IF(D21="No Cumple",0,"NA")) -> NA
B22: 1.8. ¿Los Programas de Liderazgo Participativo de SST se evalúan semanalmente? | D22: Cumple | G22: =IF(D22="Cumple",1,IF(D22="No Cumple",0,"NA")) -> 1
F23: Cumplimiento Parcial | G23: =SUMIF(G15:G22,"<2") -> 4
G24: =IFERROR((G23*1)/(COUNTIF(G15:G22,"<2")),"NA") -> 0.57142857

Sheet Nivel 2
B6: Centro de trabajo: | C6: ='Nivel 1'!C9 -> Oficina Central | D6: Cliente: | E6: ='Nivel 1'!E9 -> Bimbo | F6: Total de Cumplimiento Informado:
B7: Administrador de obra: | C7: ='Nivel 1'!C10 -> Franklin Bratta | D7: Fecha inicio del Proyecto:
B8: Experto en Prevención de Riesgos de Obra: | C8: ='Nivel 1'!C11 -> Loreto lopez | D8: Hora de Inicio: | E8: ='Nivel 1'!E11 -> 0.5 | F8: Total de Cumplimiento Verificado: | H8: Cumple
B9: Fecha: | D9: Hora de Termino: | E9: ='Nivel 1'!E12 -> 0.75 | F9: =G23 -> 1 | H9: No Cumple
H10: No Aplica
B11: GENERALIDADES DE IMPLEMENTACIÓN | D11: Cumple/No Cumple No Aplica | E11: OBSERVACIONES | G11: Subtotal
B12: 2.1. ¿Se evidencia que la línea de Supervisión realiza ART diariamente y cada vez que las condiciones del área cambien se vuelve analizar el ART ? RG-SST-61 | D12: Cumple | G12: =IF(D12="Cumple",1,IF(D12="No Cumple",0,"NA")) -> 1
B13: 2.2. ¿Se ha implementado Minuta IRL, con la medición de sus test de conocimiento?, de acuerdo al Art.15 del DS.44 RG-SST-16; RG-SST-20 | D13: Cumple | G13: =IF(D13="Cumple",1,IF(D13="No Cumple",0,"NA")) -> 1
B14: 2.4. ¿Existen medios para la consulta y participación de los trabajadores en obra? | D14: Cumple | G14: =IF(D14="Cumple",1,IF(D14="No Cumple",0,"NA")) -> 1
B15: 2.5. ¿Se evidencia registro de entrega de Procedimiento de Trabajo Seguro donde se establecen los métodos de trabajo correcto, riesgos y medidas de control? RG-SST-23 | D15: Cumple | G15: =IF(D15="Cumple",1,IF(D15="No Cumple",0,"NA")) -> 1
B16: 2.6 ¿Se encuentra firmado el Programa SST por el Gerente General / Administrador de Obra y el Prevencionista de Riesgo? | D16: Cumple | G16: =IF(D16="Cumple",1,IF(D16="No Cumple",0,"NA")) -> 1
B17: 2.7 ¿Se encuentran firmados los procedimientos de implementación del sistema de gestión de SST? | D17: Cumple | G17: =IF(D17="Cumple",1,IF(D17="No Cumple",0,"NA")) -> 1
B18: 2.8. ¿El sistema de gestión esta ordenado según lo indicado en cada lomo de los archivadores, encontrándose la documentación de manera fisica en estos? | D18: Cumple | G18: =IF(D18="Cumple",1,IF(D18="No Cumple",0,"NA")) -> 1
B19: 2.9. ¿Se ingresa semanalmente la documentación al DRIVE de SST? | D19: Cumple | G19: =IF(D19="Cumple",1,IF(D19="No Cumple",0,"NA")) -> 1
B20: 2.10. Cuenta con registro de inducción de todos los riesgos asociados y medidas preventivas para trabajadores propios y contratistas (considerar distintos idiomas en caso de inmigrantes). | D20: Cumple | G20: =IF(D20="Cumple",1,IF(D20="No Cumple",0,"NA")) -> 1
B21: 2.11. ¿Se entrega de forma fisica o digital el RIOHS actualizado, quedando registro de la firma del trabajador(a)? | D21: Cumple | G21: =IF(D21="Cumple",1,IF(D21="No Cumple",0,"NA")) -> 1
F22: Cumplimiento Parcial | G22: =SUMIF(G12:G21,"<2") -> 10
G23: =IFERROR((G22*1)/(COUNTIF(G12:H21,"<2")),"NA") -> 1

Sheet Nivel 3
B6: Centro de trabajo: | C6: ='Nivel 1'!C9 -> Oficina Central | D6: Cliente: | E6: ='Nivel 1'!E9 -> Bimbo | F6: Total de Cumplimiento Informado:
B7: Administrador de obra: | C7: ='Nivel 1'!C10 -> Franklin Bratta | D7: Fecha inicio del Proyecto: | E7: ='Nivel 1'!E10 -> 45763
B8: Experto en Prevención de Riesgos de Obra: | C8: ='Nivel 1'!C11 -> Loreto lopez | D8: Hora de Inicio: | E8: ='Nivel 1'!E11 -> 0.5 | F8: Total de Cumplimiento Verificado: | H8: Cumple
B9: Fecha: | C9: ='Nivel 1'!C12 -> 45763 | D9: Hora de Termino: | E9: ='Nivel 1'!E12 -> 0.75 | F9: =G21 -> NA | H9: No Cumple
H10: No Aplica
B11: ELEMENTOS DE PROTECCIÓN PERSONAL (EPP) | D11: Cumple/No Cumple No Aplica | E11: OBSERVACIONES | G11: Subtotal
B12: 3.1. ¿Se evidencia registro de Entrega Inicial de EPP? RG-SST-21 | G12: =IF(D12="Cumple",1,IF(D12="No Cumple",0,"NA")) -> NA
B13: 3.2. ¿Se evidencia registro de reposición de EPP específicos; Auditivo y Respiratorio, estos indican la marca y modelo en el registro ? RG-SST-08 | G13: =IF(D13="Cumple",1,IF(D13="No Cumple",0,"NA")) -> NA
B14: 3.3. ¿Se ha capacitado a los trabajadores en la Importancia, uso y mantención de los EPP? RG-SGI-02 | G14: =IF(D14="Cumple",1,IF(D14="No Cumple",0,"NA")) -> NA
B15: 3.4. ¿Se evidencia adiestramiento de Elementos de Protección Personal para los trabajadores? (SGSST-PG-13-R-03 al SGSST-PG-13-R-08) | G15: =IF(D15="Cumple",1,IF(D15="No Cumple",0,"NA")) -> NA
B16: 3.5. ¿La línea de mando inspecciona los Elementos de Protección Personal de los trabajadores quincenalmente? RG-SST-69 | G16: =IF(D16="Cumple",1,IF(D16="No Cumple",0,"NA")) -> NA
B17: 3.6. ¿La línea de Supervisión inspecciona los Elementos de Protección Personal de sus trabajadores específicamente (arnés, protección auditiva, protección respiratoria)? RG-SST-70 | G17: =IF(D17="Cumple",1,IF(D17="No Cumple",0,"NA")) -> NA
B18: 3.7. ¿Los EPP cuentan con certificación actualizada y vigente? | G18: =IF(D18="Cumple",1,IF(D18="No Cumple",0,"NA")) -> NA
B19: 3.8. ¿Se evidencia Matriz de Elementos de Protección Personal de la Obra de todos los cargos de obra? RG-SST-62 | G19: =IF(D19="Cumple",1,IF(D19="No Cumple",0,"NA")) -> NA
F20: Cumplimiento Parcial | G20: =SUMIF(G12:G19,"<2") -> 0
G21: =IFERROR((G20*1)/(COUNTIF(G12:G19,"<2")),"NA") -> NA

Sheet Nivel 4
B6: Centro de trabajo: | C6: ='Nivel 1'!C9 -> Oficina Central | D6: Cliente: | E6: ='Nivel 1'!E9 -> Bimbo | F6: Total de Cumplimiento Informado:
B7: Administrador de obra: | C7: ='Nivel 1'!C10 -> Franklin Bratta | D7: Fecha inicio del Proyecto: | E7: ='Nivel 1'!E10 -> 45763
B8: Experto en Prevención de Riesgos de Obra: | C8: ='Nivel 1'!C11 -> Loreto lopez | D8: Hora de Inicio: | E8: ='Nivel 1'!E11 -> 0.5 | F8: Total de Cumplimiento Verificado: | H8: Cumple
B9: Fecha: | C9: ='Nivel 1'!C12 -> 45763 | D9: Hora de Termino: | E9: ='Nivel 1'!E12 -> 0.75 | F9: =G19 -> NA | H9: No Cumple
H10: No Aplica
B11: IDENTIFICACIÓN DE PELIGROS Y EVALUACIÓN DE RIESGOS (IPER) | D11: Cumple/No Cumple No Aplica | E11: OBSERVACIONES | G11: Subtotal
B12: 4.1. ¿La obra establece el procedimiento de Implementación para la Gestión del Riesgo? PTS-SST-34 Evidenciar mediante firma del documento. | G12: =IF(D12="Cumple",1,IF(D12="No Cumple",0,"NA")) -> NA
B13: 4.2. ¿Supervisores, línea de mando, CPHS, incluidas las empresas contratistas y subcontratistas han sido capacitados en Taller IPER? Dictado por Mutual o por el Experto SST de obra RG-SGI-02 | G13: =IF(D13="Cumple",1,IF(D13="No Cumple",0,"NA")) -> NA
B14: 4.3. ¿La actualización de la Matriz ha sido aprobada por el Administrador de Obra y revisada por trabajadores o partes interesadas (CPHS, Jefes de área y supervisores)? Se evidencia mediante firma RG-SST-108 | G14: =IF(D14="Cumple",1,IF(D14="No Cumple",0,"NA")) -> NA
B15: 4.4. Se revisa y actualiza la Matriz IPER semestralmente, cuando sucedan accidentes y/o cuando se planifican actividades extraordinarias en obra. RG-SST-108 | G15: =IF(D15="Cumple",1,IF(D15="No Cumple",0,"NA")) -> NA
B16: 4.5. ¿Se ha difundido Matriz IPER a todos los trabajadores (propios y de empresas contratistas), línea de mando y CPHS de la obra? RG-SGI-02 | G16: =IF(D16="Cumple",1,IF(D16="No Cumple",0,"NA")) -> NA
B17: 4.6. ¿La matriz IPER incorpora todos los agentes que se exponen los trabajadores? (Sílice, Ruido, MMC, TMERT EESS, RUV, Riesgos Psicosociales, Hipobaria, Vibraciones, Metales Pesados, Polvo de Madera, Solventes, etc.? | G17: =IF(D17="Cumple",1,IF(D17="No Cumple",0,"NA")) -> NA
F18: Cumplimiento Parcial | G18: =SUMIF(G12:G17,"<2") -> 0
G19: =IFERROR((G18*1)/(COUNTIF(G12:G17,"<2")),"NA") -> NA

Sheet Nivel 5
B6: Centro de trabajo: | C6: ='Nivel 1'!C9 -> Oficina Central | D6: Cliente: | E6: ='Nivel 1'!E9 -> Bimbo | F6: Total de Cumplimiento Informado:
B7: Administrador de obra: | C7: ='Nivel 1'!C10 -> Franklin Bratta | D7: Fecha inicio del Proyecto: | E7: ='Nivel 1'!E10 -> 45763
B8: Experto en Prevención de Riesgos de Obra: | C8: ='Nivel 1'!C11 -> Loreto lopez | D8: Hora de Inicio: | E8: ='Nivel 1'!E11 -> 0.5 | F8: Total de Cumplimiento Verificado: | H8: Cumple
B9: Fecha: | C9: ='Nivel 1'!C12 -> 45763 | D9: Hora de Termino: | E9: ='Nivel 1'!E12 -> 0.75 | F9: =G20 -> NA | H9: No Cumple
H10: No Aplica
B11: PROCEDIMIENTOS GENERALES Y ESPECÍFICOS DE SEGURIDAD | D11: Cumple/No Cumple No Aplica | E11: OBSERVACIONES | G11: Subtotal
B12: 5.1. ¿Se evidencian Procedimientos de Trabajo Seguro Específicos para todas las actividades en ejecución en la obra? Evidencia procedimiento firmado por cada partida de obra. | G12: =IF(D12="Cumple",1,IF(D12="No Cumple",0,"NA")) -> NA
B13: 5.2. ¿Se evidencia la Entrega de Procedimiento de Trabajo Seguro y Capacitación a la Línea de mando de la obra? RG-SGI-02 | C13: 6.3. ¿Se evidencia la Entrega de Procedimiento de Trabajo Seguro y Capacitación de la Lí­nea de mando de la obra? (SGSSO-PG-28-R-01) | G13: =IF(D13="Cumple",1,IF(D13="No Cumple",0,"NA")) -> NA
B14: 5.3. ¿Se evidencia la Entrega de Procedimiento de Trabajo Seguro y Capacitación al Comité Paritario de la obra? RG-SST-23 | C14: 6.4. ¿Se evidencia la Entrega de Procedimiento de Trabajo Seguro y Capacitación del Comité Paritario de la obra? (SGSSO-PG-28-R-01) | G14: =IF(D14="Cumple",1,IF(D14="No Cumple",0,"NA")) -> NA
B15: 5.4. ¿Se evidencia la difusión Procedimiento de Trabajo Seguro y Capacitación de todos los trabajadores de la obra? RG-SGI-02 | C15: 6.7. ¿Se evidencia la Entrega de Procedimiento de Trabajo Seguro y Capacitación de todos los trabajadores de la obra? (SGSSO-PG-28-R-01) | G15: =IF(D15="Cumple",1,IF(D15="No Cumple",0,"NA")) -> NA
B16: 5.5. ¿Existe responsable en los procedimientos de la coordinación para el desarrollo de las diferentes partidas, controlando la interacción de los riesgos? | G16: =IF(D16="Cumple",1,IF(D16="No Cumple",0,"NA")) -> NA
B17: 5.6. ¿Se controla el cumplimiento de los procedimientos, mediante reportes de hallazgos en el GHIF? | G17: =IF(D17="Cumple",1,IF(D17="No Cumple",0,"NA")) -> NA
B18: 5.7. ¿Se evidencian los Procedimientos de Trabajo Seguro Generales? Evidenciar procedimientos firmados | C18: 6.5. ¿Se evidencian Procedimientos de Trabajo Seguro Generales? | G18: =IF(D18="Cumple",1,IF(D18="No Cumple",0,"NA")) -> NA
F19: Cumplimiento Parcial | G19: =SUMIF(G12:G18,"<2") -> 0
G20: =IFERROR((G19*1)/(COUNTIF(G12:G18,"<2")),"NA") -> NA

Sheet Nivel 6
B6: Centro de trabajo: | C6: ='Nivel 1'!C9 -> Oficina Central | D6: Cliente: | E6: ='Nivel 1'!E9 -> Bimbo | F6: Total de Cumplimiento Informado:
B7: Administrador de obra: | C7: ='Nivel 1'!C10 -> Franklin Bratta | D7: Fecha inicio del Proyecto: | E7: ='Nivel 1'!E10 -> 45763
B8: Experto en Prevención de Riesgos de Obra: | C8: ='Nivel 1'!C11 -> Loreto lopez | D8: Hora de Inicio: | E8: ='Nivel 1'!E11 -> 0.5 | F8: Total de Cumplimiento Verificado: | H8: Cumple
B9: Fecha: | C9: ='Nivel 1'!C12 -> 45763 | D9: Hora de Termino: | E9: ='Nivel 1'!E12 -> 0.75 | F9: =G28 -> NA | H9: No Cumple
H10: No Aplica
B11: INSTALACIÓN DE FAENA | D11: Cumple/No Cumple No Aplica | E11: OBSERVACIONES | G11: Subtotal
B12: 6.1 ¿La instalación de faena cuenta con un Plano de Extintores y en cantidad suficiente según el DS 594? | G12: =IF(D12="Cumple",1,IF(D12="No Cumple",0,"NA")) -> NA
B13: 6.2. ¿Cuenta con la cantidad de servicios higiénicos independientes, separados por sexo, en buen estado de limpieza y funcionamiento? De acuerdo al DS N°594 (articulo 23) | C13: 7.3. ¿Cuenta con servicios higiénicos independientes y separados por sexo? | G13: =IF(D13="Cumple",1,IF(D13="No Cumple",0,"NA")) -> NA
B14: 6.3. ¿El comedor cumple con las condiciones mínimas establecidas por la autoridad sanitaria: Mesas y Sillas con cubierta de material lavable y piso solido de fácil limpieza. Agua potable, lavaplatos, medio de refrigeración, cocinilla y energía eléctrica? | C14: 7.4. ¿EL comedor cumple con las condiciones mí­nimas establecidas por la autoridad sanitaria: Mesas y Sillas con cubierta de material lavable y piso solido de facil limpieza. Agua potable, lavaplatos, medio de refigeración, cocinilla y energí­a eléctrica? | G14: =IF(D14="Cumple",1,IF(D14="No Cumple",0,"NA")) -> NA
B15: 6.4. ¿La instalación de faena cuenta con una Estación de emergencia con todas las condiciones definidas por el Procedimiento de Emergencia? PTS-SST-37 | C15: 7.6. ¿La instalación de faena cuenta con una Estación de emergencia con todas las condiciones definidas por el Sistema de Gestión? (SGSSO-PG-06-R-03) | G15: =IF(D15="Cumple",1,IF(D15="No Cumple",0,"NA")) -> NA
B16: 6.5. Los extintores que se ubican a la intemperie se encuentran en gabinetes que permiten su retiro expedito? | C16: 7.10. Los extintores que se ubican a la intemperie se encuentran en gabinetes que permiten su retiro expedito? | G16: =IF(D16="Cumple",1,IF(D16="No Cumple",0,"NA")) -> NA
B17: 6.6. ¿Los conductores eléctricos y enchufes se encuentran en buen estado? | C17: 7.11. ¿Los conductores eléctricos y enchufes se encuentran en buen estado? | G17: =IF(D17="Cumple",1,IF(D17="No Cumple",0,"NA")) -> NA
B18: 6.7. ¿El plan de emergencia considera eventos que se pueden producir en la instalación de faena? | C18: 7.12. ¿El plan de emergencia considera eventos que se pueden producir en la instalación de faena? | G18: =IF(D18="Cumple",1,IF(D18="No Cumple",0,"NA")) -> NA
B19: 6.8. ¿La Bodega de Combustibles, Gases Comprimidos, Residuos Peligrosos cuenta con extintores de incendio? | C19: 7.16. ¿La Bodega de Combustibles, Gases Comprimidos, Residuos Peligrosos cuenta con extintores de incendio? | G19: =IF(D19="Cumple",1,IF(D19="No Cumple",0,"NA")) -> NA
B20: 6.9. ¿El comedor se encuentra completamente aislado de las áreas de trabajo y de cualquier fuente de contaminación ambiental? | C20: 7.19. ¿El comedor se encuentra completamente aislado de las áreas de trabajo y de cualquier fuente de contaminación ambiental? | G20: =IF(D20="Cumple",1,IF(D20="No Cumple",0,"NA")) -> NA
B21: 6.10. ¿Cuenta con vías de Evacuación y Salidas de Emergencia, puntos de encuentro de emergencia, correctamente identificadas mediante señalización visible y permanente? | C21: 7.20. ¿Cuenta con ví­as de Evacuación y Salidas de Emergencia, correctamente identificadas mediante señalización visible y permanente? | G21: =IF(D21="Cumple",1,IF(D21="No Cumple",0,"NA")) -> NA
B22: 6.11. ¿Las duchas están dotadas de agua fría y caliente? | C22: 7.25. ¿Las duchas están dotadas de agua frí­a y caliente? | G22: =IF(D22="Cumple",1,IF(D22="No Cumple",0,"NA")) -> NA
B23: 6.12. ¿Cuenta con el numero adecuado de casilleros guardarropas? (trabajadores están expuestos a sustancias tóxicas o infecciosas, éstos deberán tener 2 casilleros individuales) | C23: 7.26. ¿Cuenta con el numero adecuado de casilleros guardarropas? (trabajadores están expuestos a sustancias tóxicas o infecciosas, éstos deberán tener 2 casilleros individuales) | G23: =IF(D23="Cumple",1,IF(D23="No Cumple",0,"NA")) -> NA
B24: 6.13. ¿Los extintores se ubican en sitios de fácil acceso y clara identificación, libres de obstáculos, colocándose a una altura máxima de 1,30 metros medidos desde el suelo a la base del extintor? | C24: 7.30. ¿Los extintores se ubican en sitios de fácil acceso y clara identificación, libres de obstáculos, colocándose a una altura máxima de 1,30 metros medidos desde el suelo a la base del extintor? | G24: =IF(D24="Cumple",1,IF(D24="No Cumple",0,"NA")) -> NA
... B26: 6.15. ¿Mantiene control de vectores de interés sanitario en la Instalación (Sanitización, Desinsección y Desratización? | C26: 7.35. ¿Mantiene control de vectores de interés sanitario en la Instalación? | G26: =IF(D26="Cumple",1,IF(D26="No Cumple",0,"NA")) -> NA
F27: Cumplimiento Parcial | G27: =SUMIF(G12:G26,"<2") -> 0
G28: =IFERROR((G27*1)/(COUNTIF(G12:G26,"<2")),"NA") -> NA

Sheet Nivel 7
B6: Centro de trabajo: | C6: ='Nivel 1'!C9 -> Oficina Central | D6: Cliente: | E6: ='Nivel 1'!E9 -> Bimbo | F6: Total de Cumplimiento Informado:
B7: Administrador de obra: | C7: ='Nivel 1'!C10 -> Franklin Bratta | D7: Fecha inicio del Proyecto: | E7: ='Nivel 1'!E10 -> 45763
B8: Experto en Prevención de Riesgos de Obra: | C8: ='Nivel 1'!C11 -> Loreto lopez | D8: Hora de Inicio: | E8: ='Nivel 1'!E11 -> 0.5 | F8: Total de Cumplimiento Verificado: | H8: Cumple
B9: Fecha: | C9: ='Nivel 1'!C12 -> 45763 | D9: Hora de Termino: | E9: ='Nivel 1'!E12 -> 0.75 | F9: =G21 -> NA | H9: No Cumple
H10: No Aplica
B11: VEHÍCULOS LIVIANOS Y MAQUINARIA PESADA | D11: Cumple/No Cumple No Aplica | E11: OBSERVACIONES | G11: Subtotal
B12: 7.1. ¿ Los operadores realizan diariamente Check List de sus Equipos Pesados a cargo antes de su utilización? | G12: =IF(D12="Cumple",1,IF(D12="No Cumple",0,"NA")) -> NA
B13: 7.2 ¿Los vehículos y maquinarias tienen un programa de mantención preventivo? Mantener todos los respaldos archivados. | G13: =IF(D13="Cumple",1,IF(D13="No Cumple",0,"NA")) -> NA
B14: 7.3. Todos los Vehículos Livianos cumplen con los requisitos definidos: Permiso de circulación al día, Revisión técnica al día, Seguro obligatorio al día, Registro de mantención vigente, Cinturón de Seguridad, Botiquín de Primeros Auxilios, Extintor de incendios vigente, todas las luces del vehículo operativas, bocina operativa, triángulos, chaleco reflectante, gata hidráulica, rueda de repuesto, Bitácora, kit de herramientas, cintas reflectoras y logos definidos en el Manual de Marca Regional. | C14: 8.2. Todos los Vehículos Livianos cumplen con los requisitos definidos por Flesan, a saber: Permiso de circulación al dí­a, Revisión técnica al dí­a, Seguro obligatorio al dí­a, Registro de mantención vigente, Cinturón de Seguridad, Botiquín de Primeros Auxilios, Extintor de incendios vigente, todas las luces del vehículo operativas, bocina operativa, triángulos, chaleco reflectante, gata hidráulica, rueda de repuesto, Bitácora, kit de herramientas, cintas reflectoras y logos definidos en el Manual de Marca Regional. | G14: =IF(D14="Cumple",1,IF(D14="No Cumple",0,"NA")) -> NA
B15: 7.4. Los vehículos utilizados para el traslado de combustibles líquidos corresponden a: camionetas 3/4 o camiones cuyo peso bruto vehicular es igual o superior a 3.500 Kg (con dos ejes) y cumplen con todos los requisitos mencionados en el punto 7.6 sobre Vehículos Pesados, así­ como también, cuentan con la autorización de la SEC para el transporte menor de combustibles lí­quidos y son utilizados sólo para estos efectos (no para trasladar personas). | C15: 8.3. Los vehiculos utilizados para el traslado de combustibles lí­quidos corresponden a: camionetas 3/4 o camiones cuyo peso bruto vehicular es igual o superior a 3.500 Kg (con dos ejes) y cumplen con todos los requisitos mencionados anteriormente el punto 8.4 sobre Vehiculos Pesados, así­ como también, cuentan con la autorización de la SEC para el transporte menor de combustibles lí­quidos y son utilizados sólo para estos efectos (no para trasladar personas). | G15: =IF(D15="Cumple",1,IF(D15="No Cumple",0,"NA")) -> NA
B16: 7.5. Todas la Maquinaria y Equipos Pesada cumplen con los requisitos definidos: Permiso de circulación (cuando aplique), Revisión técnica, Seguro obligatorio, Mantención vigente, Protección de las partes móviles, alarma de retroceso, baliza luminosa, cinturón de seguridad de tres puntas, botiquín de primeros auxilios, cabinas aisladas de las condiciones exteriores y con aire acondicionado/calefacción, extintor de incendios, todas las luces del equipo operativas, todos los neumáticos en perfecto estado, bocina, triángulos, kit de herramientas, vidrios transparentes, cintas reflectantes y logos definidos en el Manual de Marca Regional (si aplica). | C16: 8.4. Todas la Maquinaria Pesada cumplen con los requisitos definidos por Flesan, a saber: Permiso de circulación (cuando aplique), Revisión técnica, Seguro obligatorio, Mantención vigente, Protección de las partes móviles, alarma de retroceso, baliza luminosa, cinturón de seguridad de tres puntas, botiquín de primeros auxilios, cabinas aisladas de las condiciones exteriores y con aire acondicionado/calefacción, extintor de incendios vigente, todas las luces del equipo operativas, todos los neumáticos en perfecto estado, bocina operativa, triángulos, kit de herramientas, cintas reflectantes y logos definidos en el Manual de Marca Regional (si aplica), vidrios transparentes. | G16: =IF(D16="Cumple",1,IF(D16="No Cumple",0,"NA")) -> NA
B17: 7.6. Los Operadores de Maquinaria Pesada cuentan con: Examen psicosensotecnico aprobado, Licencia de conducir vigente de acuerdo al tipo de Equipo a operar, cursos de conducción a la defensiva y/o conducción en condiciones climáticas adversas aprobado, Contrato de trabajo/Anexo de modificación de funciones (donde se incluyan las labores de operador de equipos pesados) Inducción respectiva. | C17: 8.5. Los Operadores de Maquinaria Pesada cuentan con: Examen psicosensotecnico aprobado, Licencia de conducir vigente de acuerdo al tipo de Equipo a operar, cursos de conducción a la defensiva y/o conducción en condiciones climáticas adversas aprobado, Contrato de trabajo/Anexo de modificación de funciones (donde se incluyan las labores de operador de equipos pesados) Inducción respectiva. | G17: =IF(D17="Cumple",1,IF(D17="No Cumple",0,"NA")) -> NA
B18: 7.7. Los Conductores de Vehículos cuentan con: Examen psicosensotecnico aprobado, Licencia de conducir vigente de acuerdo al tipo de vehículo, cursos de conducción a la defensiva y/o conducción en condiciones climáticas adversas aprobado, Anexo de modificación de funciones (donde se incluyan las labores de conductor) e inducción (ODI) especifica. | C18: 8.6. Los Conductores de Vehículos cuentan con: Examen psicosensotecnico aprobado, Licencia de conducir vigente de acuerdo al tipo de vehículo, cursos de conducción a la defensiva y/o conducción en condiciones climáticas adversas aprobado, Anexo de modificación de funciones (donde se incluyan las labores de conductor) e inducción (ODI) especifica. | G18: =IF(D18="Cumple",1,IF(D18="No Cumple",0,"NA")) -> NA
B19: 7.8. ¿Se evidencia registro de recepción conforme del vehículo, equipo o maquinaria Pesada, realizado por el Experto SST y el encargado de Maquinarias (si no existe el Administrador de Contrato debe definir responsable)? (Chequeo inicial, al llegar a obra) | C19: 8.9. ¿Se evidencia registro de recepción conforme del vehículo o maquinaria Pesada, realizado por el Experto SSO? (Chequeo inicial, al llegar a obra) | G19: =IF(D19="Cumple",1,IF(D19="No Cumple",0,"NA")) -> NA
F20: Cumplimiento Parcial | G20: =SUMIF(G12:G19,"<2") -> 0
G21: =IFERROR((G20*1)/(COUNTIF(G12:G19,"<2")),"NA") -> NA

Sheet Nivel 8
B6: Centro de trabajo: | C6: ='Nivel 1'!C9 -> Oficina Central | D6: Cliente: | E6: ='Nivel 1'!E9 -> Bimbo | F6: Total de Cumplimiento Informado:
B7: Administrador de obra: | C7: ='Nivel 1'!C10 -> Franklin Bratta | D7: Fecha inicio del Proyecto: | E7: ='Nivel 1'!E10 -> 45763
B8: Experto en Prevención de Riesgos de Obra: | C8: ='Nivel 1'!C11 -> Loreto lopez | D8: Hora de Inicio: | E8: ='Nivel 1'!E11 -> 0.5 | F8: Total de Cumplimiento Verificado: | H8: Cumple
B9: Fecha: | D9: Hora de Termino: | E9: ='Nivel 1'!E12 -> 0.75 | F9: =G25 -> NA | H9: No Cumple
H10: No Aplica
B11: REPORTE DE HALLAZGOS E INCIDENTES | D11: Cumple/No Cumple No Aplica | E11: OBSERVACIONES | G11: Subtotal
B12: 8.1. Todas las investigaciones de accidentes del trabajo ¿incluyen la declaración del trabajador involucrado y de testigos? RG-SST-114 | G12: =IF(D12="Cumple",1,IF(D12="No Cumple",0,"NA")) -> NA
B13: 8.2. ¿Se genera Reporte Flash (Alto potencial) en un plazo no superior a 24 horas (Incidentes) y 48 horas (accidentes y graves)? | C13: 11.3. ¿Se genera Reporte Flash de Seguridad por cada Incidente ocurrido en obra? | G13: =IF(D13="Cumple",1,IF(D13="No Cumple",0,"NA")) -> NA
B14: 8.3. Se difunden y analizan en obra los Incidentes ocurridos en ella, así como los reportes flash enviados por correo de otras obras, para obtener aprendizajes? RG-SST-120 | C14: 11.5. Se difunden en obra los Incidentes ocurridos en ella, así­ como los reportes flash relevantes de otras obras, para obtener aprendizajes, evitanto la recurrencia/ocurrencia de los mismos? (SGSSO-PG-28-R-01) | G14: =IF(D14="Cumple",1,IF(D14="No Cumple",0,"NA")) -> NA
B15: 8.4. Cuando los incidentes se materializan producto de acciones inseguras ¿Se reinstruye a los trabajadores respecto a los métodos de trabajo correctos, riesgos y medidas de control? RG-SGI-02 | C15: 11.4. Cuando los incidentes se materializan producto de acciones inseguras ¿Se reinstruye a los trabajadores respecto a los métodos de trabajo correctos, riesgos y medidas de control? (SGSSO-PG-28-R-01) | G15: =IF(D15="Cumple",1,IF(D15="No Cumple",0,"NA")) -> NA
B16: 8.5. Cuando los incidentes se materializan producto de condiciones inseguras ¿Se corrigen todas aquellas que provocaron el incidente y se mantienen a través del tiempo? | C16: 11.6. Cuando los incidentes se materializan producto de condiciones inseguras ¿Se corrigen todas aquellas que provocaron el incidente? | G16: =IF(D16="Cumple",1,IF(D16="No Cumple",0,"NA")) -> NA
B17: 8.6. Las personas que se accidentan a causa o con ocasión del trabajo ¿son derivadas a Mutual de Seguridad para su oportuna atención? (Ingreso DIAT 24 hrs) | C17: 11.8. Las personas que se accidentan a causa o con ocasión del trabajo ¿son derivadas a Mutual de Seguridad para su oportuna atención? | G17: =IF(D17="Cumple",1,IF(D17="No Cumple",0,"NA")) -> NA
B18: 8.7. ¿Todos los incidentes de obra son reportados? (Cuasi Accidentes, Daño Material, Falla Operacional, Accidentes y enfermedades con y sin tiempo perdido) | C18: 11.9. ¿Todos los incidentes de obra son reportados? (Cuasi Accidentes, Daño Material, Falla Operacional, Accidentes con y sin tiempo perdido) | G18: =IF(D18="Cumple",1,IF(D18="No Cumple",0,"NA")) -> NA
B19: 8.8. ¿Todos los Programas de Liderazgo Activo de SST de la obra consideran al menos generar 1 reporte de Hallazgo a través de la APP GHIF a la semana? | G19: =IF(D19="Cumple",1,IF(D19="No Cumple",0,"NA")) -> NA
B20: 8.9. ¿Se da cumplimiento durante la semana a la cantidad de reportes de Hallazgos definidos en los Programas de Liderazgo a través de la APP GHIF? (4 por cada Programa de Liderazgo de SST) | C20: 19.2. ¿Se da cumplimiento durante la semana a la cantidad de reportes de Hallazgos definidos en todos los planes personalizados a través de la APP GHIF? | G20: =IF(D20="Cumple",1,IF(D20="No Cumple",0,"NA")) -> NA
B21: 8.10. ¿Se cierra el 95% de los reportes de alto potencial en un plazo no mayor a 72 horas? | C21: 19.4. ¿Se cierra el 80% de los reportes Indeseables e Inaceptables de la semana antes de las 100 horas? | G21: =IF(D21="Cumple",1,IF(D21="No Cumple",0,"NA")) -> NA
B22: 8.11. ¿Se encuentra cerrado al menos el 80% de los reportes totales de la obra? | C22: 19.5. ¿Se encuentra cerrado al menos el 80% de los reportes totales de la obra? | G22: =IF(D22="Cumple",1,IF(D22="No Cumple",0,"NA")) -> NA
B23: 8.12. ¿Los accidentes o incidentes de alto potencial son investigados por el AO - JT - SUP - CPHS de la Obra, CPHS? RG-SST-113 | C23: 11.10. ¿Los incidentes son investigados por la Lí­nea de Mando de la Obra? (SGSSO-PI-05-R-03) | G23: =IF(D23="Cumple",1,IF(D23="No Cumple",0,"NA")) -> NA
F24: Cumplimiento Parcial | G24: =SUMIF(G12:G23,"<2") -> 0
G25: =IFERROR((G24*1)/(COUNTIF(G12:G23,"<2")),"NA") -> NA

Sheet Nivel 9
B6: Centro de trabajo: | C6: ='Nivel 1'!C9 -> Oficina Central | D6: Cliente: | E6: ='Nivel 1'!E9 -> Bimbo | F6: Total de Cumplimiento Informado:
B7: Administrador de obra: | C7: ='Nivel 1'!C10 -> Franklin Bratta | D7: Fecha inicio del Proyecto: | E7: ='Nivel 1'!E10 -> 45763
B8: Experto en Prevención de Riesgos de Obra: | C8: ='Nivel 1'!C11 -> Loreto lopez | D8: Hora de Inicio: | E8: ='Nivel 1'!E11 -> 0.5 | F8: Total de Cumplimiento Verificado: | H8: Cumple
B9: Fecha: | C9: ='Nivel 1'!C12 -> 45763 | D9: Hora de Termino: | E9: ='Nivel 1'!E12 -> 0.75 | F9: =G29 -> NA | H9: No Cumple
H10: No Aplica
B11: COMITÉ PARITARIO DE HIGIENE Y SEGURIDAD | D11: Cumple/No Cumple No Aplica | E11: OBSERVACIONES | G11: Subtotal
B12: 9.1. ¿Se ha Constituido Comité Paritario de Higiene y Seguridad en la Obra? RG-SST-35 | G12: =IF(D12="Cumple",1,IF(D12="No Cumple",0,"NA")) -> NA
B13: 9.2. El Comité Paritario ¿cuenta con un programa de trabajo para el año en curso? ¿Mantiene los registros del cumplimiento de las actividades programadas? RG-SST-39 | C13: 13.2. El Comité Paritario ¿cuenta con un programa de trabajo para el año en curso? (SGSSO-PG-03-R-02) | G13: =IF(D13="Cumple",1,IF(D13="No Cumple",0,"NA")) -> NA
B14: 9.3. ¿Se realiza seguimiento mensual (mínimo) a las recomendaciones y puntos acordados en las reuniones de CPHS? RG-SST-38 | C14: 13.3. Se realiza seguimiento a las recomendaciones y puntos acordados en las reuniones de CPHS? (SGSSO-PG-03-R-01) | G14: =IF(D14="Cumple",1,IF(D14="No Cumple",0,"NA")) -> NA
B15: 9.4. ¿El Comité Paritario realiza reuniones mensuales y se deja registro de la misma en las respectivas actas? RG-SST-38 | C15: 13.4. El Comité Paritario ¿realiza reuniones mensuales y se deja registro de la misma en las respectivas actas? (SGSSO-PG-03-R-01) | G15: =IF(D15="Cumple",1,IF(D15="No Cumple",0,"NA")) -> NA
B16: 9.5 ¿Se designa entre sus integrantes un presidente y secretario dejándolo estipulado en un acta? | G16: =IF(D16="Cumple",1,IF(D16="No Cumple",0,"NA")) -> NA
B17: 9.6. ¿Se ha remitido Copia del Acta de Constitución a la Dirección del Trabajo, SEREMI de Salud y Mutual de Seguridad CCHC? (Anexo Carta de Comunicación Constitución Comité Paritario) | C17: 13.5. ¿Se ha remitido Copia del Acta de Constitución a la Dirección del Trabajo, SEREMI de Salud y Mutual de Seguridad CCHC? (Anexo Carta de Comunicación Constitución Comité Paritario) | G17: =IF(D17="Cumple",1,IF(D17="No Cumple",0,"NA")) -> NA
B18: 9.7. ¿El comité paritario se encuentra certificado en una categoría (bronce-plata-oro) Cuando tiene 6 meses de funcionamiento? | C18: 13.6. ¿Todos los miembros del CPHS cuentan con curso de Orientación en Prevención de Riesgos dictado por Mutual, aprobado? | G18: =IF(D18="Cumple",1,IF(D18="No Cumple",0,"NA")) -> NA
B19: 9.8. ¿El Comité investiga las causas de los todos los accidentes CTP e incidentes de alto potencial, determinando medidas de control? | C19: 13.6. ¿Todos los miembros del CPHS cuentan con curso de Orientación en Prevención de Riesgos dictado por Mutual, aprobado? | G19: =IF(D19="Cumple",1,IF(D19="No Cumple",0,"NA")) -> NA
B20: 9.9. ¿Se analizan en la reunión mensual los accidentes, enfermedades profesionales y los reportes GHIF ocurridos en el mes anterior ? | G20: =IF(D20="Cumple",1,IF(D20="No Cumple",0,"NA")) -> NA
B21: 9.10. ¿Se realiza seguimiento a la eficacia de las medidas de control indicada en las investigación de accidentes y enfermedades profesionales? | G21: =IF(D21="Cumple",1,IF(D21="No Cumple",0,"NA")) -> NA
B22: 9.11. ¿Se promueve la realización de cursos de adiestramiento destinado a la capacitación de los trabajadores? | G22: =IF(D22="Cumple",1,IF(D22="No Cumple",0,"NA")) -> NA
B23: 9.12. ¿El comité asesora e instruye a los trabajadores en el uso y mantención de EPP, medidas de control a tareas críticas, medidas de control de agentes físicos, químicos y biológicos? | G23: =IF(D23="Cumple",1,IF(D23="No Cumple",0,"NA")) -> NA
B24: 9.13. ¿Participa el presidente o un representante de los trabajadores en el comité de ejecutivo de obra de forma mensual? | G24: =IF(D24="Cumple",1,IF(D24="No Cumple",0,"NA")) -> NA
B25: 9.14. ¿Participa un representante de los trabajadores en el comité de aplicación del protocolo de riesgos psicosocial? | G25: =IF(D25="Cumple",1,IF(D25="No Cumple",0,"NA")) -> NA
B26: 9.15. ¿El Comité Paritario incorpora en su Cronograma de trabajo actividades relacionadas con la prevención de la Hipoacusia, TMERT EESS, Riesgos Psicosociales y PLANESI? | G26: =IF(D26="Cumple",1,IF(D26="No Cumple",0,"NA")) -> NA
B27: 9.16. ¿Todos los miembros del CPHS cuentan con curso de Orientación en Prevención de Riesgos (mínimo 4 horas) dictado por Mutual, aprobado? | C27: 13.6. ¿Todos los miembros del CPHS cuentan con curso de Orientación en Prevención de Riesgos dictado por Mutual, aprobado? | G27: =IF(D27="Cumple",1,IF(D27="No Cumple",0,"NA")) -> NA
F28: Cumplimiento Parcial | G28: =SUMIF(G12:G27,"<2") -> 0
G29: =IFERROR((G28*1)/(COUNTIF(G12:G27,"<2")),"NA") -> NA

Sheet Nivel 10
B4: Centro de trabajo: | C4: ='Nivel 1'!C9 -> Oficina Central | D4: Cliente: | E4: ='Nivel 1'!E9 -> Bimbo | F4: Total de Cumplimiento Informado:
B5: Administrador de obra: | C5: ='Nivel 1'!C10 -> Franklin Bratta | D5: Fecha inicio del Proyecto: | E5: ='Nivel 1'!E10 -> 45763
B6: Experto en Prevención de Riesgos de Obra: | C6: ='Nivel 1'!C11 -> Loreto lopez | D6: Hora de Inicio: | E6: ='Nivel 1'!E11 -> 0.5 | F6: Total de Cumplimiento Verificado: | H6: Cumple
B7: Fecha: | C7: ='Nivel 1'!C12 -> 45763 | D7: Hora de Termino: | E7: ='Nivel 1'!E12 -> 0.75 | F7: =G19 -> NA | H7: No Cumple
H8: No Aplica
B9: SUBCONTRATOS | D9: Cumple/No Cumple No Aplica | E9: OBSERVACIONES | G9: Subtotal
B10: 10.1. ¿La empresa contratista o subcontratista entrega su Plan y Programa de Gestión de Seguridad y Salud en el Trabajo? | C10: 14.2. ¿Los trabajadores de la empresa contratista o subcontratista, utilizan en las faenas todos sus elementos de protección personal? | G10: =IF(D10="Cumple",1,IF(D10="No Cumple",0,"NA")) -> NA
B11: 10.2. ¿La empresa contratista o subcontratista, ha presentado Matriz IPER (actualizada para el proyecto), Procedimientos de Trabajo Seguro o Instructivos Específicos para el desarrollo de los trabajos en obra? | C11: 14.3. ¿La empresa contratista o subcontratista, ha remitido Copia de su Reglamento Interno Vigente, Matriz IPER, Procedimientos de Trabajo Seguro e Instructivos Esecí­ficos para el desarrollo de los trabajos en obra? | G11: =IF(D11="Cumple",1,IF(D11="No Cumple",0,"NA")) -> NA
B12: 10.3. ¿Se solicita Certificado de Adhesión a un organismo administrador de la Ley 16.744? | C12: 14.5. ¿Se solicita Certificado de Adhesión a un organismo administrador de la Ley 16.744? | G12: =IF(D12="Cumple",1,IF(D12="No Cumple",0,"NA")) -> NA
B13: 10.4. ¿La empresa contratista y/o subcontratista, ha remitido las cartas de entrega de Reglamento Interno (actualizado) a SEREMI de Salud y DT? | C13: 14.6. ¿La empresa contratista y/o subcontratista, ha remitido copia de las cartas de entrega de Reglamento Interno vigente a los organismos competentes? | G13: =IF(D13="Cumple",1,IF(D13="No Cumple",0,"NA")) -> NA
B14: 10.5. ¿La empresa contratista o subcontratista, ha remitido toda la documentación de SST por cada uno de sus trabajadores? (Inducción, ODI, examenes preocupacionales u ocupacionales, Entrega de RIOHS, Entrega de EPP, Capacitación en PTS, Capacitación Matriz IPER, Capacitación Uso y Manejo de Extintores, u otros específicos del cargo, todos con test de evaluación (medición de eficacia)? | C14: 14.7. ¿La empresa contratista o subcontratista, ha remitido toda la documentación de SSO por cada uno de sus trabajadores? (Inducción, ODI, Entrega de RIOHS, Entrega de EPP, Capacitación en PTS, Capacitación Matriz IPER, Capacitación Uso y Manejo de Extintores, u otros especificos del cargo? | G14: =IF(D14="Cumple",1,IF(D14="No Cumple",0,"NA")) -> NA
B15: 10.6. ¿Se ha entregado copia del Reglamento Especial para empresas Contratistas y Subcontratistas, dejando registro de ello? (SGSST-PG-02-R-05) | G15: =IF(D15="Cumple",1,IF(D15="No Cumple",0,"NA")) -> NA
B16: 10.7. ¿Certificado de calidad de los Elementos de Protección Personal que utilizan en faena? | G16: =IF(D16="Cumple",1,IF(D16="No Cumple",0,"NA")) -> NA
B17: 10.8. Cuando existen más de 50 trabajadores en obra, sin importar su dependencia ¿Se solicita Programa de Prevención de Riesgos, aprobado por su representante legal, a Empresas Contratista y Subcontratista? | C17: 14.14. Cuando existen mí¡s de 50 trabajadores en obra, sin importar su dependencia ¿Se solicita Programa de Prevención de Riesgos, aprobado por su representante legal, a Empresas Contratista ySubcontratista? | G17: =IF(D17="Cumple",1,IF(D17="No Cumple",0,"NA")) -> NA
F18: Cumplimiento Parcial | G18: =SUMIF(G10:G17,"<2") -> 0
G19: =IFERROR((G18*1)/(COUNTIF(G10:G17,"<2")),"NA") -> NA

Sheet Nivel 11
B5: Centro de trabajo: | C5: ='Nivel 1'!C9 -> Oficina Central | D5: Cliente: | E5: ='Nivel 1'!E9 -> Bimbo | F5: Total de Cumplimiento Informado:
B6: Administrador de obra: | C6: ='Nivel 1'!C10 -> Franklin Bratta | D6: Fecha inicio del Proyecto: | E6: ='Nivel 1'!E10 -> 45763
B7: Experto en Prevención de Riesgos de Obra: | C7: ='Nivel 1'!C11 -> Loreto lopez | D7: Hora de Inicio: | E7: ='Nivel 1'!E11 -> 0.5 | F7: Total de Cumplimiento Verificado: | H7: Cumple
B8: Fecha: | C8: ='Nivel 1'!C12 -> 45763 | D8: Hora de Termino: | E8: ='Nivel 1'!E12 -> 0.75 | H8: No Cumple
H9: No Aplica
B10: FORMACIÓN Y DESARROLLO | D10: Cumple/No Cumple No Aplica | E10: OBSERVACIONES | G10: Subtotal
B11: 11.1. ¿Existe Programa de Formación y Desarrollo? ¿Ha sido aprobado por el Administrador de Obra? | G11: =IF(D11="Cumple",1,IF(D11="No Cumple",0,"NA")) -> NA
B12: 11.2. ¿El Programa considera actividades desarrolladas por Mutual de Seguridad C.Ch.C, dirijido a la línea de mando, profesionales, comité paritario y trabajadores? | C12: 16.2. ¿El Programa considera actividades desarrolladas por Mutual de Seguridad C.Ch.C.? | G12: =IF(D12="Cumple",1,IF(D12="No Cumple",0,"NA")) -> NA
B13: 11.3. ¿Los encargados de realizar y validar los Analisis de Riesgos del Trabajo (ART), cuenta con capacitación aprobada, en cuanto a la aplicación de dicha herramienta? | G13: =IF(D13="Cumple",1,IF(D13="No Cumple",0,"NA")) -> NA
B14: 11.4 ¿El Programa de Formación y Desarrollo incluye capacitaciones específicas, sobre plan de emergencia, extintores, uso, mantención y almacenamiento de EPP, Matriz de Riesgos, protocolos MINSAL y Guías Técnicas del ISP, etc? | G14: =IF(D14="Cumple",1,IF(D14="No Cumple",0,"NA")) -> NA
B15: 11.5. ¿Se actualiza el programa al desarrollar las actividades de capacitación en obra? | C15: 16.5. ¿Se actualiza el programa al desarrollar las actividades de capacitación en obra? | G15: =IF(D15="Cumple",1,IF(D15="No Cumple",0,"NA")) -> NA
B16: 11.6. ¿Se reprograman las capacitaciones que no se realizan durante el mes? ¿Actualizando el Programa? | C16: 16.6. ¿Se encuentran capacitados todos los trabajadores en las distintas actividades programadas? | G16: =IF(D16="Cumple",1,IF(D16="No Cumple",0,"NA")) -> NA
B17: 11.7. ¿Todas las capacitaciones tienen medición de eficacia; test de evaluación del aprendizaje? (considerar distintos idiomas en caso de inmigrantes). | G17: =IF(D17="Cumple",1,IF(D17="No Cumple",0,"NA")) -> NA
B18: 11.8. ¿El Programa considera actividades desarrolladas por el Experto de la Obra y Proveedores? | C18: 16.7. ¿El Programa considera actividades desarrolladas por el Experto de la Obra? | G18: =IF(D18="Cumple",1,IF(D18="No Cumple",0,"NA")) -> NA
F19: Cumplimiento Parcial | G19: =SUMIF(G11:G18,"<2") -> 0
G20: =IFERROR((G19*1)/(COUNTIF(G11:G18,"<2")),"NA") -> NA

Sheet Nivel 12
B6: Centro de trabajo: | C6: ='Nivel 1'!C9 -> Oficina Central | D6: Cliente: | E6: ='Nivel 1'!E9 -> Bimbo | F6: Total de Cumplimiento Informado:
B7: Administrador de obra: | C7: ='Nivel 1'!C10 -> Franklin Bratta | D7: Fecha inicio del Proyecto: | E7: ='Nivel 1'!E10 -> 45763
B8: Experto en Prevención de Riesgos de Obra: | C8: ='Nivel 1'!C11 -> Loreto lopez | D8: Hora de Inicio: | E8: ='Nivel 1'!E11 -> 0.5 | F8: Total de Cumplimiento Verificado: | H8: Cumple
B9: Fecha: | C9: ='Nivel 1'!C12 -> 45763 | D9: Hora de Termino: | E9: ='Nivel 1'!E12 -> 0.75 | F9: =G19 -> 1 | H9: No Cumple
H10: No Aplica
B11: SALUD EN EL TRABAJO | D11: Cumple/No Cumple No Aplica | E11: OBSERVACIONES | G11: Subtotal
B12: ¿Se ha implementado el Plan de Gestión de Salud en el Trabajo? (SGSST-PI-08) | D12: Cumple | G12: =IF(D12="Cumple",1,IF(D12="No Cumple",0,"NA")) -> 1
B13: ¿Se coordinan con Mutual de Seguridad el ingreso de los trabajadores expuestos a agentes al Plan de Vigilancia Médica? (SGSST-PI-08) | D13: Cumple | G13: =IF(D13="Cumple",1,IF(D13="No Cumple",0,"NA")) -> 1
B14: ¿Se coordinan con Mutual de Seguridad las evaluaciones Post-Ocupacionales de los trabajadores al termino de exposición del agente? (SGSST-PI-08-02) | D14: Cumple | G14: =IF(D14="Cumple",1,IF(D14="No Cumple",0,"NA")) -> 1
B15: ¿Se elabora el Programa Salud en el Trabajo? ¿Es aprobado y firmado por el Administrador de Obra? (cronograma de actividades? | D15: Cumple | G15: =IF(D15="Cumple",1,IF(D15="No Cumple",0,"NA")) -> 1
B16: ¿Se coordina con Mutual de Seguridad el primer mes de operación de la obra un PGP? | D16: Cumple | G16: =IF(D16="Cumple",1,IF(D16="No Cumple",0,"NA")) -> 1
B17: ¿Se evidencia que en las visitas de Mutual de Seguridad, se verifique la implementación de Protocolos y Guías Técnicas? | D17: Cumple | G17: =IF(D17="Cumple",1,IF(D17="No Cumple",0,"NA")) -> 1
F18: Cumplimiento Parcial | G18: =SUMIF(G12:G17,"<2") -> 6
G19: =IFERROR((G18*1)/(COUNTIF(G12:G17,"<2")),"NA") -> 1

Sheet Nivel 13
B4: Centro de trabajo: | C4: ='Nivel 1'!C9 -> Oficina Central | D4: Cliente: | E4: ='Nivel 1'!E9 -> Bimbo | F4: Total de Cumplimiento Informado:
B5: Administrador de obra: | C5: ='Nivel 1'!C10 -> Franklin Bratta | D5: Fecha inicio del Proyecto: | E5: ='Nivel 1'!E10 -> 45763
B6: Experto en Prevención de Riesgos de Obra: | C6: ='Nivel 1'!C11 -> Loreto lopez | D6: Hora de Inicio: | E6: ='Nivel 1'!E11 -> 0.5 | F6: Total de Cumplimiento Verificado: | H6: Cumple
B7: Fecha: | C7: ='Nivel 1'!C12 -> 45763 | D7: Hora de Termino: | E7: ='Nivel 1'!E12 -> 0.75 | F7: =G20 -> 0.77777778 | H7: No Cumple
H8: No Aplica
B9: GUÍA TÉCNICA RADIACIÓN UV | D9: Cumple/No Cumple No Aplica | E9: OBSERVACIONES | G9: Subtotal
B10: 13.1. ¿Se elabora el Plan Protección UV de origen Solar (SGSST-PI-08-06)? ¿Es aprobado y firmado por el Administrador de Obra? | D10: Cumple | G10: =IF(D10="Cumple",1,IF(D10="No Cumple",0,"NA")) -> 1
B11: 13.2. ¿Se elabora el Programa de Protección UV de origen Solar (SGSST-PI-08-06-R-01)? ¿Es aprobado y firmado por el Administrador de Obra? | D11: No Cumple | G11: =IF(D11="Cumple",1,IF(D11="No Cumple",0,"NA")) -> 0
B12: 13.3. ¿Se mantiene actualizada la matriz IPER incluyendo la identificación de los peligros, evaluación de los riesgos y medidas de control asociados a la Radiación UV de Origen Solar? | D12: No Cumple | G12: =IF(D12="Cumple",1,IF(D12="No Cumple",0,"NA")) -> 0
B13: 13.4. ¿Se realizó la difusión de la Guía Técnica de radiación ultravioleta solar? | C13: 19.2. ¿Se realizó la difusión de la Guía Técnica de radiación ultravioleta solar? | D13: Cumple | G13: =IF(D13="Cumple",1,IF(D13="No Cumple",0,"NA")) -> 1
B14: 13.5. ¿La empresa cuenta con un Programa de Capacitación teórico-práctico para los trabajadores expuestos a radiación ultravioleta solar? | C14: 19.3. ¿La empresa cuenta con un Programa de Capacitación teórico-práctico para los trabajadores expuestos a radiación ultravioleta solar? | D14: Cumple | G14: =IF(D14="Cumple",1,IF(D14="No Cumple",0,"NA")) -> 1
B15: 13.6. ¿Los vehículos o equipos operados al aire libre, cuentan con cabinas, parabrisas y vidrios laterales con láminas reductoras de radiación UV-A? | C15: 19.6. ¿Los vehículos o equipos operados al aire libre, cuentan con cabinas, parabrisas y vidrios laterales con láminas reductoras de radiación UV-A? | D15: Cumple | G15: =IF(D15="Cumple",1,IF(D15="No Cumple",0,"NA")) -> 1
B16: 13.7. ¿En operaciones con exposición directa a UV solar, se dispone y se usan elementos de protección personal acordes con el tipo de exposición solar? | C16: 19.9. ¿En operaciones con exposición directa a UV solar, se dispone y se usan elementos de protección personal acordes con el tipo de exposición solar? | D16: Cumple | G16: =IF(D16="Cumple",1,IF(D16="No Cumple",0,"NA")) -> 1
B17: 13.8. ¿Se remitió el registro de la difusión de la Guía Técnica de radiación ultravioleta solar a la Seremi de Salud e Inspección del Trabajo correspondiente? | C17: 19.10. ¿Se remitió el registro de la difusión de la Guía Técnica de radiación ultravioleta solar a la Seremi de Salud e Inspección del Trabajo correspondiente? | D17: Cumple | G17: =IF(D17="Cumple",1,IF(D17="No Cumple",0,"NA")) -> 1
B18: 13.9. ¿Se publica diariamente y en un lugar visible el Índice de Radiación UV estimado y señalado por la Dirección Meteorológica de Chile? | C18: 19.12. ¿Se publica diariamente y en un lugar visible el Índice de Radiación UV estimado y señalado por la Dirección Meteorológica de Chile? | D18: Cumple | G18: =IF(D18="Cumple",1,IF(D18="No Cumple",0,"NA")) -> 1
F19: Cumplimiento Parcial | G19: =SUMIF(G10:G18,"<2") -> 7
G20: =IFERROR((G19*1)/(COUNTIF(G10:G18,"<2")),"NA") -> 0.77777778

Sheet Nivel 14
B6: Centro de trabajo: | C6: ='Nivel 1'!C9 -> Oficina Central | D6: Cliente: | E6: ='Nivel 1'!E9 -> Bimbo | F6: Total de Cumplimiento Informado:
B7: Administrador de obra: | C7: ='Nivel 1'!C10 -> Franklin Bratta | D7: Fecha inicio del Proyecto: | E7: ='Nivel 1'!E10 -> 45763
B8: Experto en Prevención de Riesgos de Obra: | C8: ='Nivel 1'!C11 -> Loreto lopez | D8: Hora de Inicio: | E8: ='Nivel 1'!E11 -> 0.5 | F8: Total de Cumplimiento Verificado: | H8: Cumple
B9: Fecha: | C9: ='Nivel 1'!C12 -> 45763 | D9: Hora de Termino: | E9: ='Nivel 1'!E12 -> 0.75 | F9: =G29 -> 1 | H9: No Cumple
H10: No Aplica
B11: PROTOCOLO PREXOR | D11: Cumple/No Cumple No Aplica | E11: OBSERVACIONES | G11: Subtotal
B12: 14.1. ¿Se elabora el Plan de Gestión para la Vigilancia PREXOR (SGSSO-PI-08-07)? ¿Es aprobado y firmado por el Administrador de Obra? | D12: Cumple | G12: =IF(D12="Cumple",1,IF(D12="No Cumple",0,"NA")) -> 1
B13: 14.2. ¿Se elabora el Programa PREXOR (SGSSO-PI-08-R-02)? ¿Es aprobado y firmado por el Administrador de Obra? | D13: Cumple | G13: =IF(D13="Cumple",1,IF(D13="No Cumple",0,"NA")) -> 1
B14: 14.3. ¿Se mantiene actualizada la matriz IPER incluyendo la identificación de los peligros, evaluación de los riesgos y medidas de control asociados a la exposición de ruido ocupacional? | D14: Cumple | G14: =IF(D14="Cumple",1,IF(D14="No Cumple",0,"NA")) -> 1
B15: 14.4. ¿La obra cuenta con acta registro de recepción de difusión del PREXOR, en Seremi de Salud e Inspección del Trabajo, según corresponda? | D15: Cumple | G15: =IF(D15="Cumple",1,IF(D15="No Cumple",0,"NA")) -> 1
B16: 14.5. Se cuenta con Evaluación Cualitativa (mes 1) y Cuantitativa (mes 4) por Mutual de Seguridad para evaluar la presencia del agente Ruido. | D16: Cumple | G16: =IF(D16="Cumple",1,IF(D16="No Cumple",0,"NA")) -> 1
B17: 14.6. Se cuenta con registro de difusión del programa de protección auditiva a trabajadores, integrantes del comité paritario (titulares y suplentes), dirigentes sindicales y empleadores. Registro firmado de capacitación. | D17: Cumple | G17: =IF(D17="Cumple",1,IF(D17="No Cumple",0,"NA")) -> 1
B18: 14.7. ¿Se realizó la difusión del Protocolo sobre normas mínimas para el desarrollo de Programas de Vigilancia de la Pérdida Auditiva por exposición a Ruido en los lugares de trabajo? | D18: Cumple | G18: =IF(D18="Cumple",1,IF(D18="No Cumple",0,"NA")) -> 1
B19: 14.8. Se cuenta con registro de difusión de los procedimientos de trabajo seguro por cada GES de todos los trabajadores involucrados (antes y después de la Cuantitativa) debe aparecer el riesgo de ruido. Registro de difusión con firmas. | D19: Cumple | G19: =IF(D19="Cumple",1,IF(D19="No Cumple",0,"NA")) -> 1
B20: 14.9. ¿Se cuenta con registro de entrega y recambio de elementos de protección auditiva a todos los trabajadores expuestos a ruido laboral? Y si están capacitados en su correcto uso, almacenamiento, mantención y pruebas de ajuste. | D20: Cumple | G20: =IF(D20="Cumple",1,IF(D20="No Cumple",0,"NA")) -> 1
B21: 14.10. Se cuenta con registro de difusión del Informe de Ruido Laboral a los trabajadores, integrantes del comité paritario (titulares y suplentes), dirigentes sindicales y empleadores. | D21: Cumple | G21: =IF(D21="Cumple",1,IF(D21="No Cumple",0,"NA")) -> 1
B22: 14.11. ¿Existe un Programa de Mantención Preventivo a los sistemas de control de ruido, herramientas, equipos, maquinarias? | D22: Cumple | G22: =IF(D22="Cumple",1,IF(D22="No Cumple",0,"NA")) -> 1
B23: 14.12. ¿La obra adopta las medidas que le prescribe la Mutual de Seguridad y envía informe de respaldo con el levantamiento de las medidas adoptadas? | D23: Cumple | G23: =IF(D23="Cumple",1,IF(D23="No Cumple",0,"NA")) -> 1
... B27: 14.16. ¿Los EPP auditivos cumplen con los criterios de certificación definidos en el DS.594 o están registrados en el RFI elaborado por el ISP? | D27: Cumple | G27: =IF(D27="Cumple",1,IF(D27="No Cumple",0,"NA")) -> 1
F28: Cumplimiento Parcial | G28: =SUMIF(G12:G27,"<2") -> 16
G29: =IFERROR((G28*1)/(COUNTIF(G12:G27,"<2")),"NA") -> 1

Sheet Nivel 15
B4: Centro de trabajo: | C4: ='Nivel 1'!C9 -> Oficina Central | D4: Cliente: | E4: ='Nivel 1'!E9 -> Bimbo | F4: Total de Cumplimiento Informado:
B5: Administrador de obra: | C5: ='Nivel 1'!C10 -> Franklin Bratta | D5: Fecha inicio del Proyecto: | E5: ='Nivel 1'!E10 -> 45763
B6: Experto en Prevención de Riesgos de Obra: | C6: ='Nivel 1'!C11 -> Loreto lopez | D6: Hora de Inicio: | E6: ='Nivel 1'!E11 -> 0.5 | F6: Total de Cumplimiento Verificado: | H6: Cumple
B7: Fecha: | C7: ='Nivel 1'!C12 -> 45763 | D7: Hora de Termino: | E7: ='Nivel 1'!E12 -> 0.75 | F7: =G25 -> 1 | H7: No Cumple
H8: No Aplica
B9: PROTOCOLO TMERT EESS | D9: Cumple/No Cumple No Aplica | E9: OBSERVACIONES | G9: Subtotal
B10: 15.1. ¿Se elabora el Plan de Gestión de TMERT EESS (SGSST-PI-08-09)? ¿Es aprobado y firmado por el Administrador de Obra? | D10: Cumple | G10: =IF(D10="Cumple",1,IF(D10="No Cumple",0,"NA")) -> 1
B11: 15.2. ¿Se elabora el Programa TMERT EESS (SGSST-PI-08-R-02)? ¿Es aprobado y firmado por el Administrador de Obra? | D11: Cumple | G11: =IF(D11="Cumple",1,IF(D11="No Cumple",0,"NA")) -> 1
B12: 15.3. ¿Se mantiene actualizada la matriz IPER incluyendo la identificación de los peligros, evaluación de los riesgos y medidas de control asociados a la exposición de TMERT EESS? | D12: Cumple | G12: =IF(D12="Cumple",1,IF(D12="No Cumple",0,"NA")) -> 1
B13: 15.4. Existe identificación de peligro en las áreas criticas de la obra (Etapa 0) y en las tareas que presentan peligro se realizaron las lista de Chequeo TMERT-ESSS Minsal (Evidenciar listas). | D13: Cumple | G13: =IF(D13="Cumple",1,IF(D13="No Cumple",0,"NA")) -> 1
B14: 15.5. La obra ha realizado la difusión de la Norma Técnica y Protocolo de TMERT-EESS a sus trabajadores. | D14: Cumple | G14: =IF(D14="Cumple",1,IF(D14="No Cumple",0,"NA")) -> 1
B15: 15.6. ¿Se realizo la Matriz TMERT-EESS de la obra y fue revisada por un Ergónomo de Mutual de Seguridad? | D15: Cumple | G15: =IF(D15="Cumple",1,IF(D15="No Cumple",0,"NA")) -> 1
B16: 15.7. En la obra han realizado el taller teórico practico para la aplicación de "Lista de Chequeo Inicial MINSAL", y han participado los implementadores por parte de la obra. (Evidenciar diplomas de Mutual de Seguridad) | C16: 21.3. La obra ha realizado la difusión de la Norma Técnica y Protocolo de TMERT-EESS a sus trabajadores. | D16: Cumple | G16: =IF(D16="Cumple",1,IF(D16="No Cumple",0,"NA")) -> 1
B17: 15.8. ¿Tiene respaldo de la evidencia de la implementación de los controles administrativos (rotaciones pausas, etc.)? | C17: 21.5. Existe identificación de peligro en las áreas criticas de la obra (Etapa 0) | D17: Cumple | G17: =IF(D17="Cumple",1,IF(D17="No Cumple",0,"NA")) -> 1
B18: 15.9 Existe evaluación del riesgo residual, post implementación de controles, antes de cumplir el 3° mes post evaluación de riesgo. (Pasos en Rojo) | C18: 21.8. Existe evaluación del riesgo residual, post implementación de controles, antes de cumplir el 3° mes post evaluación de riesgo. (Pasos en Rojo) | D18: Cumple | G18: =IF(D18="Cumple",1,IF(D18="No Cumple",0,"NA")) -> 1
B19: 15.10. ¿Se adoptan medidas de control ingenieril? Evidenciar la eficiencia de las medidas de control. | C19: 21.9. ¿Se adoptan medidas de control ingenieril? Evidenciar la eficiencia de las medidas de control. | D19: Cumple | G19: =IF(D19="Cumple",1,IF(D19="No Cumple",0,"NA")) -> 1
B20: 15.11. ¿La obra realiza acciones para la mitigación o eliminación de los riesgos identificados y evaluados? Evidencia de las medidas implementadas. | C20: 21.10. ¿La obra realiza acciones para la mitigación o eliminación de los riesgos identificados y evaluados? Evidencia de las medidas implementadas. | D20: Cumple | G20: =IF(D20="Cumple",1,IF(D20="No Cumple",0,"NA")) -> 1
B21: 15.12. Se han realizado reuniones con áreas donde se presentaron tareas rojas, para analizar resultados, determinar y jerarquizar los controles que eliminaran/mitigaran el riesgo. | C21: 21.12. Se han realizado reuniones con áreas donde se presentaron tareas rojas, para analizar resultados, determinar y jerarquizar los controles que eliminaran/mitigaran el riesgo. | D21: Cumple | G21: =IF(D21="Cumple",1,IF(D21="No Cumple",0,"NA")) -> 1
B22: 15.13. ¿La empresa informo a todos los trabajadores (GES) y CPHS de los resultados de las tareas evaluadas (listas de chequeo)? | C22: 21.15. ¿La empresa informo a los trabajadores y CPHS, Sindicatos de los resultados de las tareas evaluadas (listas de chequeo)? | D22: Cumple | G22: =IF(D22="Cumple",1,IF(D22="No Cumple",0,"NA")) -> 1
B23: 15.14. La obra ingreso al Programa de Vigilancia los trabajadores el listado correspondiente a tareas con nivel del riesgo Alto (Rojo). | C23: 21.16. La obra ingreso al Programa de Vigilancia los trabajadores el listado correspondiente a tareas rojas. | D23: Cumple | G23: =IF(D23="Cumple",1,IF(D23="No Cumple",0,"NA")) -> 1
F24: Cumplimiento Parcial | G24: =SUMIF(G10:G23,"<2") -> 14
G25: =IFERROR((G24*1)/(COUNTIF(G10:G23,"<2")),"NA") -> 1

Sheet Nivel 16
B6: Centro de trabajo: | C6: ='Nivel 1'!C9 -> Oficina Central | D6: Cliente: | E6: ='Nivel 1'!E9 -> Bimbo | F6: Total de Cumplimiento Informado:
B7: Administrador de obra: | C7: ='Nivel 1'!C10 -> Franklin Bratta | D7: Fecha inicio del Proyecto: | E7: ='Nivel 1'!E10 -> 45763
B8: Experto en Prevención de Riesgos de Obra: | C8: ='Nivel 1'!C11 -> Loreto lopez | D8: Hora de Inicio: | E8: ='Nivel 1'!E11 -> 0.5 | F8: Total de Cumplimiento Verificado: | H8: Cumple
B9: Fecha: | C9: ='Nivel 1'!C12 -> 45763 | D9: Hora de Termino: | E9: ='Nivel 1'!E12 -> 0.75 | F9: =G22 -> 1 | H9: No Cumple
H10: No Aplica
B11: PROTOCOLO DE VIGILANCIA DE RIESGOS PSICOSOCIALES | D11: Cumple/No Cumple No Aplica | E11: OBSERVACIONES | G11: Subtotal
B12: 16.1. ¿Se elabora el Plan de Gestión de Riesgos Psicosociales (SGSST-PI-08-05)? ¿Es aprobado y firmado por el Administrador de Obra? | D12: Cumple | G12: =IF(D12="Cumple",1,IF(D12="No Cumple",0,"NA")) -> 1
B13: 16.2. ¿Se elabora el Programa de Riesgos Psicosociales (SGSST-PI-08-R-02)? ¿Es aprobado y firmado por el Administrador de Obra? | D13: Cumple | G13: =IF(D13="Cumple",1,IF(D13="No Cumple",0,"NA")) -> 1
B14: 16.3. ¿Se mantiene actualizada la matriz IPER incluyendo la identificación de los peligros, evaluación de los riesgos y medidas de control asociados a la exposición de Riesgos Psicosociales? | D14: Cumple | G14: =IF(D14="Cumple",1,IF(D14="No Cumple",0,"NA")) -> 1
B15: 16.4. Se formo el comité de aplicación (Riesgos Psicosociales) Se evidencia la constitución y funcionamiento del Comité y el seguimiento a medidas de control (Actas mensuales) y Carta Gantt (SGSST-PI-08-R-02 ). | D15: Cumple | G15: =IF(D15="Cumple",1,IF(D15="No Cumple",0,"NA")) -> 1
B16: 16.5. Serealiza la sensibilización atoda la obra | D16: Cumple | G16: =IF(D16="Cumple",1,IF(D16="No Cumple",0,"NA")) -> 1
B17: 16.6. Aplico el instrumento CEAL-SM /SUSESO. (Si es en fisico, se debe pasar a la plataforma de SUSESO) | D17: Cumple | G17: =IF(D17="Cumple",1,IF(D17="No Cumple",0,"NA")) -> 1
B18: 16.7. Cuenta con Informe de resultados de aplicación de instrumento CEAL-SM /SUSESO. ¿Se presento los resultados, discución y analisis? | C18: 22.2. Cuenta con registro de difusión de resultados obtenidos. | D18: Cumple | G18: =IF(D18="Cumple",1,IF(D18="No Cumple",0,"NA")) -> 1
B19: 16.8. Se proponenen las medidas de intervención para cada Dimensión. | C19: 22.4. Se encuentra evidencia del Comité de Aplicación en el seguimiento a medidas de control (Actas mensuales) y Carta Gantt (SGSSO-PI-08-R-02 ). | D19: Cumple | G19: =IF(D19="Cumple",1,IF(D19="No Cumple",0,"NA")) -> 1
B20: 16.9. Se realiza monitoreo y verificación a las medidasd e intervención por dimensión. | C20: 22.10. Se realiza reevaluación en las fechas determinadas de acuerdo a lo indicado en informe de resultados. | D20: Cumple | G20: =IF(D20="Cumple",1,IF(D20="No Cumple",0,"NA")) -> 1
F21: Cumplimiento Parcial | G21: =SUMIF(G12:G20,"<2") -> 9
G22: =IFERROR((G21*1)/(COUNTIF(G12:G20,"<2")),"NA") -> 1

Sheet Nivel 17
B5: Centro de trabajo: | C5: ='Nivel 1'!C9 -> Oficina Central | D5: Cliente: | E5: ='Nivel 1'!E9 -> Bimbo | F5: Total de Cumplimiento Informado:
B6: Administrador de obra: | C6: ='Nivel 1'!C10 -> Franklin Bratta | D6: Fecha inicio del Proyecto: | E6: ='Nivel 1'!E10 -> 45763
B7: Experto en Prevención de Riesgos de Obra: | C7: ='Nivel 1'!C11 -> Loreto lopez | D7: Hora de Inicio: | E7: ='Nivel 1'!E11 -> 0.5 | F7: Total de Cumplimiento Verificado: | H7: Cumple
B8: Fecha: | C8: ='Nivel 1'!C12 -> 45763 | D8: Hora de Termino: | E8: ='Nivel 1'!E12 -> 0.75 | F8: =G23 -> 1 | H8: No Cumple
H9: No Aplica
B10: GUÍA TÉCNICA MMC | D10: Cumple/No Cumple No Aplica | E10: OBSERVACIONES | G10: Subtotal
B11: 17.1. ¿Se elabora el Plan de Gestión de Manejo Manual de Cargas (SGSST-PI-08-010)? ¿Es aprobado y firmado por el Administrador de Obra? | D11: Cumple | G11: =IF(D11="Cumple",1,IF(D11="No Cumple",0,"NA")) -> 1
B12: 17.2. ¿Se elabora el Programa de Manejo Manual de Cargas (SGSST-PI-08-R-02)? ¿Es aprobado y firmado por el Administrador de Obra? | D12: Cumple | G12: =IF(D12="Cumple",1,IF(D12="No Cumple",0,"NA")) -> 1
